<?xml version="1.0"?>
<robot name="ucsd_kart" xmlns:xacro="http://ros.org/wiki/xacro">
    <!-- Define robot constants -->
    <xacro:property name="base_width" value="0.31"/>
    <xacro:property name="base_length" value="1.00"/>
    <xacro:property name="base_height" value="0.18"/>

    <xacro:property name="wheel_radius" value="0.10"/>
    <xacro:property name="wheel_width" value="0.04"/>
    <xacro:property name="wheel_ygap" value="0.025"/>
    <xacro:property name="wheel_zoff" value="0.05"/>
    <xacro:property name="wheel_xoff" value="${base_length/2-0.15}"/>

    <!-- Define intertial property macros  -->
    <xacro:macro name="box_inertia" params="m w h d">
        <inertial>
        <origin xyz="0 0 0" rpy="${pi/2} 0 ${pi/2}"/>
        <mass value="${m}"/>
        <inertia ixx="${(m/12) * (h*h + d*d)}" ixy="0.0" ixz="0.0" iyy="${(m/12) * (w*w + d*d)}" iyz="0.0" izz="${(m/12) * (w*w + h*h)}"/>
        </inertial>
    </xacro:macro>

    <xacro:macro name="cylinder_inertia" params="m r h">
        <inertial>
        <origin xyz="0 0 0" rpy="${pi/2} 0 0" />
        <mass value="${m}"/>
        <inertia ixx="${(m/12) * (3*r*r + h*h)}" ixy = "0" ixz = "0" iyy="${(m/12) * (3*r*r + h*h)}" iyz = "0" izz="${(m/2) * (r*r)}"/>
        </inertial>
    </xacro:macro>

    <!-- Robot Base -->
    <link name="base_link">
        <visual>
            <geometry>
                <box size="${base_length} ${base_width} ${base_height}"/>
            </geometry>
            <material name="Cyan">
                <color rgba="0 1.0 1.0 1.0"/>
            </material>
        </visual>
        <collision>
            <geometry>
              <box size="${base_length} ${base_width} ${base_height}"/>
            </geometry>
          </collision>
      
          <xacro:box_inertia m="15" w="${base_width}" d="${base_length}" h="${base_height}"/>      
    </link>

    <!-- Robot Footprint -->
    <link name="base_footprint"/>

    <joint name="base_joint" type="fixed">
        <parent link="base_link"/>
        <child link="base_footprint"/>
        <origin xyz="0.0 0.0 ${-(wheel_radius+wheel_zoff)}" rpy="0 0 0"/>
    </joint>

    <!-- Back wheel macros -->
    <xacro:macro name="wheel" params="prefix x_reflect y_reflect parent_link">
        <link name="${prefix}_link">
            <visual>
                <origin xyz="0 0 0" rpy="${pi/2} 0 0"/>
                <geometry>
                    <cylinder radius="${wheel_radius}" length="${wheel_width}"/>
                </geometry>
                <material name="Gray">
                    <color rgba="0.5 0.5 0.5 1.0"/>
                </material>
            </visual>
            <collision>
                <origin xyz="0 0 0" rpy="${pi/2} 0 0"/>
                <geometry>
                  <cylinder radius="${wheel_radius}" length="${wheel_width}"/>
                </geometry>
              </collision>
        
              <xacro:cylinder_inertia m="0.5" r="${wheel_radius}" h="${wheel_width}"/>        
        </link>

        <joint name="${prefix}_joint" type="continuous">
            <parent link="${parent_link}"/>
            <child link="${prefix}_link"/>
            <origin xyz="${x_reflect*wheel_xoff} ${y_reflect*(base_width/2+wheel_ygap)} ${-wheel_zoff}" rpy="0 0 0"/>
            <axis xyz="0 1 0"/>
        </joint>
    </xacro:macro>
    
    <!-- Create back wheels -->
    <xacro:wheel prefix="drivewhl_rl" x_reflect="-1" y_reflect="1" parent_link="base_link"/>
    <xacro:wheel prefix="drivewhl_rr" x_reflect="-1" y_reflect="-1" parent_link="base_link"/>

    
    
   <!-- FRONT WHEELS-->
   <link name="steering_link">
        <origin xyz="${wheel_xoff} 0 ${-wheel_zoff}" rpy="0 0 0"/>
    </link>

    <joint name="steering_joint" type="revolute">
        <parent link="base_link"/>
        <child link="steering_link"/>
        <axis xyz="0 0 1" rpy="0 0 0" />
        <limit effort="100" velocity="1" lower="-1" upper="1"/> 
        <origin xyz="${wheel_xoff} 0 ${-wheel_zoff}" rpy="0 0 0"/>
    </joint>

    <xacro:macro name="wheel_steer" params="prefix x_reflect y_reflect parent_link">
        <link name="${prefix}_wheel_hinge_link"/>
        <joint name="${prefix}_wheel_hinge_joint" type="revolute">
            <parent link="${parent_link}"/>
            <child link="${prefix}_wheel_hinge_link"/>
            <axis xyz="0 0 1" rpy="0 0 0" />
            <limit effort="100" velocity="1" lower="-1" upper="1"/> 
            <origin xyz="0 ${y_reflect*(base_width/2+wheel_ygap)} 0"/>
        </joint>
        <link name="${prefix}_wheel_link">
            <visual>
                <origin xyz="0 0 0" rpy="${pi/2} 0 0"/>
                <geometry>
                    <cylinder radius="${wheel_radius}" length="${wheel_width}"/>
                </geometry>
                <material name="Gray">
                    <color rgba="0.5 0.5 0.5 1.0"/>
                </material>
            </visual>
            <collision>
                <origin xyz="0 0 0" rpy="${pi/2} 0 0"/>
                <geometry>
                  <cylinder radius="${wheel_radius}" length="${wheel_width}"/>
                </geometry>
              </collision>
        
              <xacro:cylinder_inertia m="0.5" r="${wheel_radius}" h="${wheel_width}"/>        
        </link>
        <joint name="${prefix}_wheel_joint" type="continuous">
            <parent link="${prefix}_wheel_hinge_link"/>
            <child link="${prefix}_wheel_link"/>
            <origin xyz="0 0 0" rpy="0 0 0"/>
            <axis xyz="0 1 0"/>
        </joint>
    </xacro:macro>

    <xacro:wheel_steer prefix="front_left" x_reflect="1" y_reflect="-1" parent_link="steering_link"/>
    <xacro:wheel_steer prefix="front_right" x_reflect="1" y_reflect="1" parent_link="steering_link"/>

</robot>